<?xml version="1.0" encoding="UTF-8"?>
<!-- Generated by org.testng.reporters.JUnitReportReporter -->
<testsuite hostname="CESIT-LAP-0420" failures="2" tests="7" name="sample.sample" time="34.411" errors="0" timestamp="2023-10-30T13:41:01 IST" skipped="2">
  <testcase classname="sample.sample" name="sample3" time="2.816"/>
  <testcase classname="sample.sample" name="sample1" time="5.691"/>
  <testcase classname="sample.sample" name="sample2" time="8.902">
    <failure message="expected [true] but found [false]" type="java.lang.AssertionError">
      <![CDATA[java.lang.AssertionError: expected [true] but found [false]
at org.testng.Assert.fail(Assert.java:111)
at org.testng.Assert.failNotEquals(Assert.java:1578)
at org.testng.Assert.assertTrue(Assert.java:57)
at org.testng.Assert.assertTrue(Assert.java:67)
at sample.sample.sample2(sample.java:22)
at java.base/jdk.internal.reflect.NativeMethodAccessorImpl.invoke0(Native Method)
at java.base/jdk.internal.reflect.NativeMethodAccessorImpl.invoke(NativeMethodAccessorImpl.java:77)
at java.base/jdk.internal.reflect.DelegatingMethodAccessorImpl.invoke(DelegatingMethodAccessorImpl.java:43)
at java.base/java.lang.reflect.Method.invoke(Method.java:568)
at org.testng.internal.invokers.MethodInvocationHelper.invokeMethod(MethodInvocationHelper.java:139)
at org.testng.internal.invokers.TestInvoker.invokeMethod(TestInvoker.java:664)
at org.testng.internal.invokers.TestInvoker.invokeTestMethod(TestInvoker.java:227)
at org.testng.internal.invokers.TestMethodWithDataProviderMethodWorker.call(TestMethodWithDataProviderMethodWorker.java:80)
at org.testng.internal.invokers.TestMethodWithDataProviderMethodWorker.call(TestMethodWithDataProviderMethodWorker.java:17)
at java.base/java.util.concurrent.FutureTask.run(FutureTask.java:264)
at java.base/java.util.concurrent.Executors$RunnableAdapter.call(Executors.java:539)
at java.base/java.util.concurrent.FutureTask.run(FutureTask.java:264)
at java.base/java.util.concurrent.ThreadPoolExecutor.runWorker(ThreadPoolExecutor.java:1136)
at java.base/java.util.concurrent.ThreadPoolExecutor$Worker.run(ThreadPoolExecutor.java:635)
at java.base/java.lang.Thread.run(Thread.java:833)
]]>
    </failure>
  </testcase> <!-- sample2 -->
  <testcase classname="sample.sample" name="sample1" time="8.626"/>
  <testcase classname="sample.sample" name="sample1" time="1.317">
    <skipped/>
  </testcase> <!-- sample1 -->
  <testcase classname="sample.sample" name="sample2" time="1.140">
    <skipped/>
  </testcase> <!-- sample2 -->
  <testcase classname="sample.sample" name="sample2" time="5.919">
    <failure message="expected [true] but found [false]" type="java.lang.AssertionError">
      <![CDATA[java.lang.AssertionError: expected [true] but found [false]
at org.testng.Assert.fail(Assert.java:111)
at org.testng.Assert.failNotEquals(Assert.java:1578)
at org.testng.Assert.assertTrue(Assert.java:57)
at org.testng.Assert.assertTrue(Assert.java:67)
at sample.sample.sample2(sample.java:22)
at java.base/jdk.internal.reflect.NativeMethodAccessorImpl.invoke0(Native Method)
at java.base/jdk.internal.reflect.NativeMethodAccessorImpl.invoke(NativeMethodAccessorImpl.java:77)
at java.base/jdk.internal.reflect.DelegatingMethodAccessorImpl.invoke(DelegatingMethodAccessorImpl.java:43)
at java.base/java.lang.reflect.Method.invoke(Method.java:568)
at org.testng.internal.invokers.MethodInvocationHelper.invokeMethod(MethodInvocationHelper.java:139)
at org.testng.internal.invokers.TestInvoker.invokeMethod(TestInvoker.java:664)
at org.testng.internal.invokers.TestInvoker.invokeTestMethod(TestInvoker.java:227)
at org.testng.internal.invokers.TestMethodWithDataProviderMethodWorker.call(TestMethodWithDataProviderMethodWorker.java:80)
at org.testng.internal.invokers.TestMethodWithDataProviderMethodWorker.call(TestMethodWithDataProviderMethodWorker.java:17)
at java.base/java.util.concurrent.FutureTask.run(FutureTask.java:264)
at java.base/java.util.concurrent.Executors$RunnableAdapter.call(Executors.java:539)
at java.base/java.util.concurrent.FutureTask.run(FutureTask.java:264)
at java.base/java.util.concurrent.ThreadPoolExecutor.runWorker(ThreadPoolExecutor.java:1136)
at java.base/java.util.concurrent.ThreadPoolExecutor$Worker.run(ThreadPoolExecutor.java:635)
at java.base/java.lang.Thread.run(Thread.java:833)
]]>
    </failure>
  </testcase> <!-- sample2 -->
</testsuite> <!-- sample.sample -->
